Workbook

Sheet README
A1: Éducation en Afrique — Projet Capstone Data Analytics
A2: Source de données : World Bank — World Development Indicators (WDI), UNESCO Institute for Statistics, IMF World Economic Outlook, ONU (population)
A3: Périmètre : 54 pays d'Afrique | Dernière année disponible par indicateur (2015-2024 selon la série)
A6: CONTENU DU CLASSEUR
A7: 1. README — ce guide
A8: 2. Data — jeu de données nettoyé, une ligne par pays (source pour Power BI)
A9: 3. Data_Dictionary — définition de chaque colonne
A10: 4. Region_Summary — agrégats par région (formules SUMIFS/AVERAGEIFS, recalculables)
A11: 5. Cleaning_Log — étapes de nettoyage appliquées et hypothèses

Sheet Data
A1: Country | B1: Region | C1: Population_2023 | D1: Population_Millions | E1: GDP_PPP_per_capita_USD | F1: GDP_per_capita_Category | G1: Literacy_Rate_Total_pct | H1: Literacy_Rate_Male_pct | I1: Literacy_Rate_Female_pct | J1: Literacy_Gender_Gap_pp | K1: Literacy_Category | L1: Literacy_Year | M1: Edu_Spending_pct_GDP | N1: Education_Investment_Category | O1: Primary_Enrollment_pct_gross | P1: Secondary_Enrollment_pct_gross | Q1: Enrollment_Drop_Primary_to_Secondary_pp | R1: Out_of_School_Risk_Index | S1: Data_Estimated_Flag
A2: Algeria | B2: North Africa | C2: 46164219 | D2: 46.16 | E2: 19677 | F2: High (>$10k) | G2: 81.4 | H2: 87.4 | I2: 75.3 | J2: 12.1 | K2: Moderate (70-85%) | L2: 2018 | M2: 5.6 | N2: Good (4-6%) | O2: 105.8 | P2: 105.2 | Q2: 0.6 | R2: 0
A3: Angola | B3: Southern Africa | C3: 36749906 | D3: 36.75 | E3: 10446 | F3: High (>$10k) | G3: 71.1 | H3: 82 | I3: 60.7 | J3: 21.3 | K3: Moderate (70-85%) | L3: 2015 | M3: 2.3 | N3: Moderate (2-4%) | O3: 113.2 | P3: 82 | Q3: 31.2 | R3: 0 | S3: Primary_Enrollment;Secondary_Enrollment;
A4: Benin | B4: West Africa | C4: 14111034 | D4: 14.11 | E4: 5088 | F4: Upper-middle ($5-10k) | G4: 42.4 | H4: 54 | I4: 31.1 | J4: 22.9 | K4: Critical (<50%) | L4: 2018 | M4: 3.4 | N4: Moderate (2-4%) | O4: 108 | P4: 47.6 | Q4: 60.4 | R4: 0 | S4: Secondary_Enrollment;
A5: Botswana | B5: Southern Africa | C5: 2480244 | D5: 2.48 | E5: 22039 | F5: High (>$10k) | G5: 88.5 | H5: 88 | I5: 88.9 | J5: 0.9 | K5: High (85%+) | L5: 2015 | M5: 8.1 | N5: High (6%+) | O5: 109.3 | P5: 82 | Q5: 27.3 | R5: 0 | S5: Secondary_Enrollment;
A6: Burkina Faso | B6: West Africa | C6: 23025776 | D6: 23.03 | E6: 3227 | F6: Lower-middle ($2-5k) | G6: 39.3 | H6: 49.2 | I6: 31 | J6: 18.2 | K6: Critical (<50%) | L6: 2018 | M6: 5.3 | N6: Good (4-6%) | O6: 82.3 | P6: 30 | Q6: 52.3 | R6: 17.7
A7: Burundi | B7: East Africa | C7: 13689450 | D7: 13.69 | E7: 1031 | F7: Low income (<$2k) | G7: 68.4 | H7: 76.3 | I7: 61.2 | J7: 15.1 | K7: Low (50-70%) | L7: 2017 | M7: 4.8 | N7: Good (4-6%) | O7: 98.1 | P7: 48.8 | Q7: 49.3 | R7: 1.9 | S7: Primary_Enrollment;Secondary_Enrollment;
A8: Cameroon | B8: Central Africa | C8: 28372687 | D8: 28.37 | E8: 5993 | F8: Upper-middle ($5-10k) | G8: 77.1 | H8: 82.6 | I8: 71.6 | J8: 11 | K8: Moderate (70-85%) | L8: 2018 | M8: 2.6 | N8: Moderate (2-4%) | O8: 112.5 | P8: 23.5 | Q8: 89 | R8: 0 | S8: Secondary_Enrollment;
A9: Cape Verde | B9: West Africa | C9: 522331 | D9: 0.52 | E9: 13313 | F9: High (>$10k) | G9: 86.8 | H9: 91.7 | I9: 82 | J9: 9.7 | K9: High (85%+) | L9: 2015 | M9: 4.7 | N9: Good (4-6%) | O9: 103 | P9: 47.6 | Q9: 55.4 | R9: 0 | S9: Secondary_Enrollment;
A10: Central African Republic | B10: Central Africa | C10: 5152421 | D10: 5.15 | E10: 1468 | F10: Low income (<$2k) | G10: 37.4 | H10: 49.5 | I10: 25.8 | J10: 23.7 | K10: Critical (<50%) | L10: 2018 | M10: 2.1 | N10: Moderate (2-4%) | O10: 99.8 | P10: 23.5 | Q10: 76.3 | R10: 0.2 | S10: Primary_Enrollment;Secondary_Enrollment;
A11: Chad | B11: Central Africa | C11: 19319064 | D11: 19.32 | E11: 3458 | F11: Lower-middle ($2-5k) | G11: 22.3 | H11: 31.3 | I11: 14 | J11: 17.3 | K11: Critical (<50%) | L11: 2016 | M11: 2.5 | N11: Moderate (2-4%) | O11: 87 | P11: 23.5 | Q11: 63.5 | R11: 13
A12: Comoros | B12: East Africa | C12: 850387 | D12: 0.85 | E12: 4222 | F12: Lower-middle ($2-5k) | G12: 58.8 | H12: 64.6 | I12: 53 | J12: 11.6 | K12: Low (50-70%) | L12: 2018 | M12: 2.4 | N12: Moderate (2-4%) | O12: 98.1 | P12: 48.8 | Q12: 49.3 | R12: 1.9 | S12: Secondary_Enrollment;
A13: Congo | B13: Central Africa | C13: 6182885 | D13: 6.18 | E13: 6712 | F13: Upper-middle ($5-10k) | G13: 80.3 | H13: 86.1 | I13: 74.6 | J13: 11.5 | K13: Moderate (70-85%) | L13: 2018 | M13: 3 | N13: Moderate (2-4%) | O13: 99.8 | P13: 23.5 | Q13: 76.3 | R13: 0.2 | S13: Primary_Enrollment;Secondary_Enrollment;
A14: DR Congo | B14: Central Africa | C14: 105789731 | D14: 105.79 | E14: 2144 | F14: Lower-middle ($2-5k) | G14: 77 | H14: 88.5 | I14: 66.5 | J14: 22 | K14: Moderate (70-85%) | L14: 2016 | M14: 3 | N14: Moderate (2-4%) | O14: 99.8 | P14: 23.5 | Q14: 76.3 | R14: 0.2 | S14: Primary_Enrollment;Secondary_Enrollment;
A15: Djibouti | B15: East Africa | C15: 1152944 | D15: 1.15 | E15: 10166 | F15: High (>$10k) | G15: 74.8 | H15: 78.4 | I15: 69.4 | J15: 11.4 | K15: Moderate (70-85%) | L15: 2018 | M15: 3.8 | N15: Moderate (2-4%) | O15: 98.1 | P15: 48.8 | Q15: 49.3 | R15: 1.9 | S15: Literacy_Rate_Total;Literacy_Rate_Male;Literacy_Rate_Female;Literacy_Gender_Gap_pp;Primary_Enrollment;Secondary_Enrollment;
A16: Egypt | B16: North Africa | C16: 114535772 | D16: 114.54 | E16: 23321 | F16: High (>$10k) | G16: 71.2 | H16: 76.5 | I16: 65.5 | J16: 11 | K16: Moderate (70-85%) | L16: 2017 | M16: 3.9 | N16: Moderate (2-4%) | O16: 89.5 | P16: 84.8 | Q16: 4.7 | R16: 10.5
A17: Equatorial Guinea | B17: Central Africa | C17: 1847549 | D17: 1.85 | E17: 19061 | F17: High (>$10k) | G17: 95.3 | H17: 97.4 | I17: 93 | J17: 4.4 | K17: High (85%+) | L17: 2015 | M17: 0.6 | N17: Low (<2%) | O17: 99.8 | P17: 23.5 | Q17: 76.3 | R17: 0.2 | S17: Primary_Enrollment;Secondary_Enrollment;
A18: Eritrea | B18: East Africa | C18: 3470390 | D18: 3.47 | E18: 4372 | F18: Lower-middle ($2-5k) | G18: 76.6 | H18: 84.4 | I18: 68.9 | J18: 15.5 | K18: Moderate (70-85%) | L18: 2018 | M18: 2.1 | N18: Moderate (2-4%) | O18: 89.7 | P18: 48.8 | Q18: 40.9 | R18: 10.3 | S18: Secondary_Enrollment;GDP_PPP_per_capita;
A19: Eswatini | B19: Southern Africa | C19: 1230506 | D19: 1.23 | E19: 14244 | F19: High (>$10k) | G19: 88.4 | H19: 88.3 | I19: 88.5 | J19: 0.2 | K19: High (85%+) | L19: 2018 | M19: 6.3 | N19: High (6%+) | O19: 117.2 | P19: 82 | Q19: 35.2 | R19: 0 | S19: Secondary_Enrollment;
A20: Ethiopia | B20: East Africa | C20: 128691692 | D20: 128.69 | E20: 4974 | F20: Lower-middle ($2-5k) | G20: 51.8 | H20: 57.2 | I20: 44.4 | J20: 12.8 | K20: Low (50-70%) | L20: 2017 | M20: 3.7 | N20: Moderate (2-4%) | O20: 84.6 | P20: 48.8 | Q20: 35.8 | R20: 15.4 | S20: Secondary_Enrollment;
A21: Gabon | B21: Central Africa | C21: 2484789 | D21: 2.48 | E21: 25847 | F21: High (>$10k) | G21: 84.7 | H21: 85.9 | I21: 83.4 | J21: 2.5 | K21: Moderate (70-85%) | L21: 2018 | M21: 2.2 | N21: Moderate (2-4%) | O21: 99.8 | P21: 23.5 | Q21: 76.3 | R21: 0.2 | S21: Primary_Enrollment;Secondary_Enrollment;
A22: Gambia | B22: West Africa | C22: 2697845 | D22: 2.7 | E22: 3865 | F22: Lower-middle ($2-5k) | G22: 50.8 | H22: 61.8 | I22: 41.6 | J22: 20.2 | K22: Low (50-70%) | L22: 2015 | M22: 2.7 | N22: Moderate (2-4%) | O22: 97.3 | P22: 47.6 | Q22: 49.7 | R22: 2.7 | S22: Secondary_Enrollment;
A23: Ghana | B23: West Africa | C23: 33787914 | D23: 33.79 | E23: 9116 | F23: Upper-middle ($5-10k) | G23: 79 | H23: 83.5 | I23: 74.5 | J23: 9 | K23: Moderate (70-85%) | L23: 2018 | M23: 2.9 | N23: Moderate (2-4%) | O23: 98.2 | P23: 75.7 | Q23: 22.5 | R23: 1.8
A24: Guinea | B24: West Africa | C24: 14405465 | D24: 14.41 | E24: 5177 | F24: Upper-middle ($5-10k) | G24: 39.6 | H24: 54.4 | I24: 27.7 | J24: 26.7 | K24: Critical (<50%) | L24: 2018 | M24: 2 | N24: Low (<2%) | O24: 97.3 | P24: 47.6 | Q24: 49.7 | R24: 2.7 | S24: Primary_Enrollment;Secondary_Enrollment;
A25: Guinea-Bissau | B25: West Africa | C25: 2153339 | D25: 2.15 | E25: 3405 | F25: Lower-middle ($2-5k) | G25: 59.9 | H25: 71.8 | I25: 48.3 | J25: 23.5 | K25: Low (50-70%) | L25: 2015 | M25: 2 | N25: Low (<2%) | O25: 97.3 | P25: 47.6 | Q25: 49.7 | R25: 2.7 | S25: Primary_Enrollment;Secondary_Enrollment;
A26: Ivory Coast | B26: West Africa | C26: 31165654 | D26: 31.17 | E26: 8672 | F26: Upper-middle ($5-10k) | G26: 89.9 | H26: 93.1 | I26: 86.7 | J26: 6.4 | K26: High (85%+) | L26: 2019 | M26: 3.4 | N26: Moderate (2-4%) | O26: 86.4 | P26: 65.3 | Q26: 21.1 | R26: 13.6
A27: Kenya | B27: East Africa | C27: 55339003 | D27: 55.34 | E27: 8020 | F27: Upper-middle ($5-10k) | G27: 81.5 | H27: 85 | I27: 78.2 | J27: 6.8 | K27: Moderate (70-85%) | L27: 2018 | M27: 4 | N27: Moderate (2-4%) | O27: 98.6 | P27: 48.8 | Q27: 49.8 | R27: 1.4 | S27: Secondary_Enrollment;
A28: Lesotho | B28: Southern Africa | C28: 2311472 | D28: 2.31 | E28: 3300 | F28: Lower-middle ($2-5k) | G28: 79.4 | H28: 70.1 | I28: 88.3 | J28: -18.2 | K28: Moderate (70-85%) | L28: 2015 | M28: 6.7 | N28: High (6%+) | O28: 83.6 | P28: 82 | Q28: 1.6 | R28: 16.4 | S28: Secondary_Enrollment;
A29: Liberia | B29: West Africa | C29: 5493031 | D29: 5.49 | E29: 2095 | F29: Lower-middle ($2-5k) | G29: 48.3 | H29: 62.7 | I29: 34.1 | J29: 28.6 | K29: Critical (<50%) | L29: 2017 | M29: 2.3 | N29: Moderate (2-4%) | O29: 66.6 | P29: 47.6 | Q29: 19 | R29: 33.4 | S29: Secondary_Enrollment;
A30: Libya | B30: North Africa | C30: 7305659 | D30: 7.31 | E30: 18749 | F30: High (>$10k) | G30: 91 | H30: 96.7 | I30: 85.6 | J30: 11.1 | K30: High (85%+) | L30: 2015 | M30: 2.3 | N30: Moderate (2-4%) | O30: 104.9 | P30: 90 | Q30: 14.9 | R30: 0 | S30: Primary_Enrollment;Secondary_Enrollment;
A31: Madagascar | B31: East Africa | C31: 31195932 | D31: 31.2 | E31: 2106 | F31: Lower-middle ($2-5k) | G31: 76.7 | H31: 78.4 | I31: 75.1 | J31: 3.3 | K31: Moderate (70-85%) | L31: 2018 | M31: 3.1 | N31: Moderate (2-4%) | O31: 132.9 | P31: 48.8 | Q31: 84.1 | R31: 0 | S31: Secondary_Enrollment;
A32: Malawi | B32: Southern Africa | C32: 21104482 | D32: 21.1 | E32: 1797 | F32: Low income (<$2k) | G32: 62.1 | H32: 69.8 | I32: 55.2 | J32: 14.6 | K32: Low (50-70%) | L32: 2015 | M32: 3.3 | N32: Moderate (2-4%) | O32: 126.6 | P32: 82 | Q32: 44.6 | R32: 0 | S32: Secondary_Enrollment;
A33: Mali | B33: West Africa | C33: 23769127 | D33: 23.77 | E33: 3665 | F33: Lower-middle ($2-5k) | G33: 35.5 | H33: 46.2 | I33: 25.7 | J33: 20.5 | K33: Critical (<50%) | L33: 2018 | M33: 4 | N33: Moderate (2-4%) | O33: 97.3 | P33: 47.6 | Q33: 49.7 | R33: 2.7 | S33: Primary_Enrollment;Secondary_Enrollment;
A34: Mauritania | B34: West Africa | C34: 5022441 | D34: 5.02 | E34: 9280 | F34: Upper-middle ($5-10k) | G34: 53.5 | H34: 63.7 | I34: 43.4 | J34: 20.3 | K34: Low (50-70%) | L34: 2017 | M34: 2.6 | N34: Moderate (2-4%) | O34: 97.3 | P34: 47.6 | Q34: 49.7 | R34: 2.7 | S34: Primary_Enrollment;Secondary_Enrollment;
A35: Mauritius | B35: Southern Africa | C35: 1273588 | D35: 1.27 | E35: 34830 | F35: High (>$10k) | G35: 91.3 | H35: 93.4 | I35: 89.4 | J35: 4 | K35: High (85%+) | L35: 2018 | M35: 4.6 | N35: Good (4-6%) | O35: 113.2 | P35: 90.7 | Q35: 22.5 | R35: 0 | S35: Primary_Enrollment;
A36: Morocco | B36: North Africa | C36: 37712505 | D36: 37.71 | E36: 12336 | F36: High (>$10k) | G36: 73.8 | H36: 83.3 | I36: 64.6 | J36: 18.7 | K36: Moderate (70-85%) | L36: 2018 | M36: 6 | N36: Good (4-6%) | O36: 116.6 | P36: 90 | Q36: 26.6 | R36: 0
A37: Mozambique | B37: Southern Africa | C37: 33635160 | D37: 33.64 | E37: 1699 | F37: Low income (<$2k) | G37: 60.7 | H37: 72.6 | I37: 50.3 | J37: 22.3 | K37: Low (50-70%) | L37: 2017 | M37: 6.2 | N37: High (6%+) | O37: 119.2 | P37: 82 | Q37: 37.2 | R37: 0 | S37: Secondary_Enrollment;
A38: Namibia | B38: Southern Africa | C38: 2963095 | D38: 2.96 | E38: 12666 | F38: High (>$10k) | G38: 91.5 | H38: 91.6 | I38: 91.4 | J38: 0.2 | K38: High (85%+) | L38: 2018 | M38: 9 | N38: High (6%+) | O38: 120.3 | P38: 82 | Q38: 38.3 | R38: 0
A39: Niger | B39: West Africa | C39: 26159867 | D39: 26.16 | E39: 2232 | F39: Lower-middle ($2-5k) | G39: 35.1 | H39: 43.6 | I39: 26.7 | J39: 16.9 | K39: Critical (<50%) | L39: 2018 | M39: 4.1 | N39: Good (4-6%) | O39: 66.2 | P39: 19.9 | Q39: 46.3 | R39: 33.8
A40: Nigeria | B40: West Africa | C40: 227882945 | D40: 227.88 | E40: 9994 | F40: Upper-middle ($5-10k) | G40: 62 | H40: 71.3 | I40: 52.7 | J40: 18.6 | K40: Low (50-70%) | L40: 2018 | M40: 0.4 | N40: Low (<2%) | O40: 97.3 | P40: 47.6 | Q40: 49.7 | R40: 2.7 | S40: Primary_Enrollment;Secondary_Enrollment;
...

Sheet Data_Dictionary
A1: Colonne | B1: Définition
A2: Country | B2: Nom du pays africain
A3: Region | B3: Sous-région Afrique (Nord, Ouest, Est, Centrale, Australe)
A4: Population_2023 | B4: Population totale, estimation la plus récente (Nations Unies / recensements officiels)
A5: Population_Millions | B5: Population exprimée en millions (colonne calculée)
A6: GDP_PPP_per_capita_USD | B6: PIB par habitant en parité de pouvoir d'achat, $ internationaux (FMI, WEO avril 2026)
A7: GDP_per_capita_Category | B7: Catégorie de revenu par habitant (colonne calculée : bins)
A8: Literacy_Rate_Total_pct | B8: Taux d'alphabétisation des adultes, total (%) — UNESCO/CIA World Factbook
A9: Literacy_Rate_Male_pct | B9: Taux d'alphabétisation des hommes adultes (%)
A10: Literacy_Rate_Female_pct | B10: Taux d'alphabétisation des femmes adultes (%)
A11: Literacy_Gender_Gap_pp | B11: Écart Homme-Femme en points de %, positif = hommes plus alphabétisés (colonne calculée)
A12: Literacy_Category | B12: Catégorisation du taux d'alphabétisation (colonne calculée : bins)
... A20: Data_Estimated_Flag | B20: Liste des champs imputés par la médiane régionale faute de donnée officielle récente (transparence méthodologique)

Sheet Region_Summary
A1: Region | B1: Nb_Pays | C1: Population_Totale | D1: PIB_par_habitant_Moyen_USD | E1: Taux_Alphabetisation_Moyen_pct | F1: Ecart_Genre_Moyen_pp | G1: Depenses_Education_pct_PIB_Moyenne | H1: Scolarisation_Primaire_Moyenne_pct | I1: Scolarisation_Secondaire_Moyenne_pct
A2: Central Africa | B2: =COUNTIF(Data!B2:B55,A2) -> 8 | C2: =SUMIF(Data!B2:B55,A2,Data!C2:C55) -> 169379997 | D2: =ROUND(AVERAGEIF(Data!B2:B55,A2,Data!E2:E55),0) -> 8924 | E2: =ROUND(AVERAGEIF(Data!B2:B55,A2,Data!G2:G55),1) -> 70.9 | F2: =ROUND(AVERAGEIF(Data!B2:B55,A2,Data!J2:J55),1) -> 12.4 | G2: =ROUND(AVERAGEIF(Data!B2:B55,A2,Data!M2:M55),1) -> 2.7 | H2: =ROUND(AVERAGEIF(Data!B2:B55,A2,Data!O2:O55),1) -> 99.8 | I2: =ROUND(AVERAGEIF(Data!B2:B55,A2,Data!P2:P55),1) -> 23.5
A3: East Africa | B3: =COUNTIF(Data!B2:B55,A3) -> 13 | C3: =SUMIF(Data!B2:B55,A3,Data!C2:C55) -> 393588416 | D3: =ROUND(AVERAGEIF(Data!B2:B55,A3,Data!E2:E55),0) -> 6736 | E3: =ROUND(AVERAGEIF(Data!B2:B55,A3,Data!G2:G55),1) -> 68.1 | F3: =ROUND(AVERAGEIF(Data!B2:B55,A3,Data!J2:J55),1) -> 9.9 | G3: =ROUND(AVERAGEIF(Data!B2:B55,A3,Data!M2:M55),1) -> 3.3 | H3: =ROUND(AVERAGEIF(Data!B2:B55,A3,Data!O2:O55),1) -> 102.5 | I3: =ROUND(AVERAGEIF(Data!B2:B55,A3,Data!P2:P55),1) -> 48.8
A4: North Africa | B4: =COUNTIF(Data!B2:B55,A4) -> 6 | C4: =SUMIF(Data!B2:B55,A4,Data!C2:C55) -> 267961377 | D4: =ROUND(AVERAGEIF(Data!B2:B55,A4,Data!E2:E55),0) -> 15395 | E4: =ROUND(AVERAGEIF(Data!B2:B55,A4,Data!G2:G55),1) -> 76.7 | F4: =ROUND(AVERAGEIF(Data!B2:B55,A4,Data!J2:J55),1) -> 12.9 | G4: =ROUND(AVERAGEIF(Data!B2:B55,A4,Data!M2:M55),1) -> 4.4 | H4: =ROUND(AVERAGEIF(Data!B2:B55,A4,Data!O2:O55),1) -> 104.3 | I4: =ROUND(AVERAGEIF(Data!B2:B55,A4,Data!P2:P55),1) -> 91.7
A5: Southern Africa | B5: =COUNTIF(Data!B2:B55,A5) -> 11 | C5: =SUMIF(Data!B2:B55,A5,Data!C2:C55) -> 202025624 | D5: =ROUND(AVERAGEIF(Data!B2:B55,A5,Data!E2:E55),0) -> 11889 | E5: =ROUND(AVERAGEIF(Data!B2:B55,A5,Data!G2:G55),1) -> 81.9 | F5: =ROUND(AVERAGEIF(Data!B2:B55,A5,Data!J2:J55),1) -> 5.2 | G5: =ROUND(AVERAGEIF(Data!B2:B55,A5,Data!M2:M55),1) -> 5.3 | H5: =ROUND(AVERAGEIF(Data!B2:B55,A5,Data!O2:O55),1) -> 110.1 | I5: =ROUND(AVERAGEIF(Data!B2:B55,A5,Data!P2:P55),1) -> 80.5
A6: West Africa | B6: =COUNTIF(Data!B2:B55,A6) -> 16 | C6: =SUMIF(Data!B2:B55,A6,Data!C2:C55) -> 446039191 | D6: =ROUND(AVERAGEIF(Data!B2:B55,A6,Data!E2:E55),0) -> 5773 | E6: =ROUND(AVERAGEIF(Data!B2:B55,A6,Data!G2:G55),1) -> 55.2 | F6: =ROUND(AVERAGEIF(Data!B2:B55,A6,Data!J2:J55),1) -> 19 | G6: =ROUND(AVERAGEIF(Data!B2:B55,A6,Data!M2:M55),1) -> 3.5 | H6: =ROUND(AVERAGEIF(Data!B2:B55,A6,Data!O2:O55),1) -> 97.5 | I6: =ROUND(AVERAGEIF(Data!B2:B55,A6,Data!P2:P55),1) -> 47.6
A7: TOTAL / MOYENNE AFRIQUE | B7: =SUM(B2:B6) -> 54 | C7: =SUM(C2:C6) -> 1478994605 | D7: =ROUND(AVERAGEIF(Data!B2:B55,"<>",Data!E2:E55),0) -> 8786 | E7: =ROUND(AVERAGE(Data!G2:G55),1) -> 68.5 | F7: =ROUND(AVERAGE(Data!J2:J55),1) -> 12.3 | G7: =ROUND(AVERAGE(Data!M2:M55),1) -> 3.8 | H7: =ROUND(AVERAGE(Data!O2:O55),1) -> 102.4 | I7: =ROUND(AVERAGE(Data!P2:P55),1) -> 55.9

Sheet Cleaning_Log
A1: Étape | B1: Description | C1: Détail
A2: 1. Collecte | B2: Compilation multi-sources | C2: Population (ONU/Wikipedia), PIB PPA/habitant (FMI WEO), alphabétisation (UNESCO/CIA), dépenses éducation %PIB (Banque Mondiale/UNESCO), scolarisation primaire & secondaire brute (UNESCO)
A3: 2. Doublons | B3: Vérification unicité pays | C3: 0 doublon détecté sur 54 pays (Country utilisé comme clé unique)
A4: 3. Valeurs manquantes | B4: Imputation par médiane régionale | C4: Pour les indicateurs sans donnée récente publiée (ex. scolarisation secondaire manquante pour ~42 pays faute de série UNESCO à jour), la valeur manquante est remplacée par la médiane de la sous-région Afrique correspondante. Chaque ligne imputée est tracée dans la colonne Data_Estimated_Flag.
A5: 4. Standardisation | B5: Noms de pays harmonisés | C5: Ivory Coast / Côte d'Ivoire, DR Congo / RD Congo, etc. harmonisés à une seule graphie anglaise pour éviter les doublons de clé
A6: 5. Formats | B6: Types de données uniformisés | C6: Population et PIB en entiers ; pourcentages arrondis à 1 décimale ; année en entier
A7: 6. Colonnes calculées | B7: Voir Data_Dictionary | C7: Population_Millions, GDP_per_capita_Category, Literacy_Category, Education_Investment_Category, Literacy_Gender_Gap_pp, Enrollment_Drop_Primary_to_Secondary_pp, Out_of_School_Risk_Index
A8: 7. Limites | B8: Hétérogénéité des années de référence | C8: Les indicateurs proviennent d'années différentes selon la dernière publication disponible par pays (2015-2024). Ceci est un standard de l'analyse WDI/UNESCO ; l'année de référence de l'alphabétisation est conservée dans Literacy_Year pour transparence.
